Workbook

Sheet 说明 README
A1: 训练字典 v2 — 说明
A3: 工作表
A4: 动作库 Exercises：每个动作一行（ID、中英文标准名、分类、器材、能否在家、要点、历史重量）。计划和记录都用动作ID。
A5: 分类 Categories：按动作模式分类，并标注大/小肌群，便于轮转。
A6: 训练组合 Workouts：原81条 + 现任教练6条（C1–C6），逐条规范重写为中英文，并拆成动作ID。
A7: 周计划 Plan：每周1次健身房（60分钟）+ 1次居家（40–45分钟）的3周轮转模板。
A8: 居家器材 Home gear：家里的器材及上限；动作库里"可在家"和"居家用法/替代"按此填写。
A9: 记录 Log：每次训练逐组记录；输入动作ID自动带出名称。
A10: 原始记录 Original：原表原文，未改动。
A12: 黄色底色 = 我对原描述的理解不确定，请你确认或修改（"待确认"列写明了原因）。
A13: 单位：lb（磅）。"档位10/12"指辅助引体向上器械的辅助档位（数字越大越省力，按你原记录推测）。
A14: "/侧"表示每侧各做该次数。

Sheet 分类 Categories
A1: 代码 Code | B1: 分类（中） | C1: Category (EN) | D1: 肌群大小 Size | E1: 轮转归属 Rotation group | F1: 动作数 # Exercises
A2: WU | B2: 热身/有氧 | C2: Warm-up & Cardio | D2: — | E2: — | F2: =COUNTIF('动作库 Exercises'!$C:$C,A2) -> 2
A3: SQ | B3: 下肢·蹲（膝主导） | C3: Lower · Squat (knee-dominant) | D3: 大 | E3: 腿 | F3: =COUNTIF('动作库 Exercises'!$C:$C,A3) -> 13
A4: HG | B4: 下肢·髋铰链（腿后侧/臀） | C4: Lower · Hinge (hamstrings & glutes) | D4: 大 | E4: 腿 | F4: =COUNTIF('动作库 Exercises'!$C:$C,A4) -> 9
A5: SL | B5: 下肢·单腿/侧向 | C5: Lower · Single-leg & Lateral | D5: 大 | E5: 腿 | F5: =COUNTIF('动作库 Exercises'!$C:$C,A5) -> 10
A6: HPU | B6: 上肢·水平推（胸） | C6: Upper · Horizontal Push (chest) | D6: 大 | E6: 胸 | F6: =COUNTIF('动作库 Exercises'!$C:$C,A6) -> 12
A7: VPL | B7: 上肢·垂直拉（背阔） | C7: Upper · Vertical Pull (lats) | D7: 大 | E7: 背 | F7: =COUNTIF('动作库 Exercises'!$C:$C,A7) -> 3
A8: HPL | B8: 上肢·水平拉（中背） | C8: Upper · Horizontal Pull (mid-back) | D8: 大 | E8: 背 | F8: =COUNTIF('动作库 Exercises'!$C:$C,A8) -> 10
A9: VPU | B9: 肩·推举 | C9: Shoulders · Overhead Press | D9: 小 | E9: 肩 | F9: =COUNTIF('动作库 Exercises'!$C:$C,A9) -> 6
A10: SH | B10: 肩·孤立（前/侧/后束） | C10: Shoulders · Isolation | D10: 小 | E10: 肩 | F10: =COUNTIF('动作库 Exercises'!$C:$C,A10) -> 7
A11: BI | B11: 手臂·二头 | C11: Arms · Biceps | D11: 小 | E11: 二头 | F11: =COUNTIF('动作库 Exercises'!$C:$C,A11) -> 4
A12: TR | B12: 手臂·三头 | C12: Arms · Triceps | D12: 小 | E12: 三头 | F12: =COUNTIF('动作库 Exercises'!$C:$C,A12) -> 8
A13: CO | B13: 核心 | C13: Core | D13: 小 | E13: 核心 | F13: =COUNTIF('动作库 Exercises'!$C:$C,A13) -> 18
... A15: BL | B15: 平衡/稳定/灵活 | C15: Balance, Stability & Mobility | D15: — | E15: 全身 | F15: =COUNTIF('动作库 Exercises'!$C:$C,A15) -> 4
A17: 大肌群 = 腿（SQ/HG/SL）、胸（HPU）、背（VPL/HPL）；小肌群 = 肩（VPU/SH）、二头（BI）、三头（TR）、核心（CO）。PW/BL 为全身/辅助类，适合热身、收尾或居家循环。

Sheet 动作库 Exercises
A1: ID | B1: 中文名 | C1: 分类代码 | D1: 分类 | E1: 肌群大小 | F1: English name | G1: 器材 Equipment | H1: 可在家 Home? | I1: 居家用法/替代 | J1: 主要肌群 | K1: 动作要点 | L1: 历史记录（来源#组合: 重量×次数） | M1: 待确认
A2: WU01 | B2: 跑步机坡度间歇 | C2: WU | D2: 热身/有氧 | E2: — | F2: Treadmill incline intervals | G2: 跑步机 | H2: N | I2: 居家可用 PW14 星跳 / 原地高抬腿 3–5分钟代替 | J2: 心肺、小腿、臀 | K2: 坡度15%；速度5 跑1分钟 + 速度2 走1分钟为1轮 | L2: #21 坡度15%：速度5 × 1分钟 + 速度2 × 1分钟
A3: WU02 | B3: 划船机 | C3: WU | D3: 热身/有氧 | E3: — | F3: Rowing machine (erg) | G3: 划船机 | H3: N | I3: 同上 | J3: 全身、背、心肺 | K3: 蹬腿→后仰→拉手，回程反序；背保持直 | L3: #3 260 m #44 1分钟 250 m #48 250 m（约2分钟）
A4: SQ01 | B4: 杠铃后蹲 | C4: SQ | D4: 下肢·蹲（膝主导） | E4: 大 | F4: Barbell back squat | G4: 杠铃+深蹲架 | H4: Y | I4: 杠铃片≤90 lb + 杆；无深蹲架需自己翻上肩，重量受限，可改前蹲 | J4: 股四头、臀、核心 | K4: 杠铃压斜方肌，挺胸收腹，蹲至大腿≥平行；可用3秒下放节奏 | L4: #2 每侧70 lb #9 每侧40 lb（总≈125 lb），3秒下放 #30 每侧45 lb（总135 lb）
A5: SQ02 | B5: 沙袋上肘前蹲 | C5: SQ | D5: 下肢·蹲（膝主导） | E5: 大 | F5: Sandbag clean to front squat | G5: 沙袋 | H5: Y | I5: 无沙袋→用杠铃翻至胸前做前蹲 | J5: 股四头、臀、上背 | K5: 沙袋从地面提至胸前，肘部抬高抱住，直背前蹲 | L5: #44 60 lb × 10
A6: SQ03 | B6: 高脚杯深蹲 | C6: SQ | D6: 下肢·蹲（膝主导） | E6: 大 | F6: Goblet squat (KB/DB) | G6: 壶铃/哑铃 | H6: Y | I6: 用单只哑铃（≤45 lb）竖握 | J6: 股四头、臀 | K6: 双手捧壶铃于胸前，肘在膝内侧，3秒下蹲 | L6: #56 35 lb，3秒下蹲 × 10 #68 30 lb × 15 #81 35 lb × 10 #81 15 lb + 起身直臂前平举 × 10
A7: SQ04 | B7: 相扑（马步）深蹲 | C7: SQ | D7: 下肢·蹲（膝主导） | E7: 大 | F7: Sumo squat (KB or bodyweight) | G7: 壶铃/自重 | H7: Y | I7: 用单只哑铃 | J7: 股四头、内收肌、臀 | K7: 宽站距脚尖外八，壶铃垂于两腿间，蹲到底起身 | L7: #31 25 lb × 10 #80 自重 × 10
A8: SQ05 | B8: 深蹲机（哈克/史密斯） | C8: SQ | D8: 下肢·蹲（膝主导） | E8: 大 | F8: Squat machine (hack / Smith) | G8: 器械 | H8: N | I8: 居家→SQ01 杠铃深蹲 | J8: 股四头、臀 | K8: 背贴靠垫，膝盖与脚尖同向 | L8: #26 每侧90 lb × 10
A9: SQ06 | B9: 腿举 | C9: SQ | D9: 下肢·蹲（膝主导） | E9: 大 | F9: Leg press | G9: 器械 | H9: N | I9: 居家→SL01 保加利亚分腿蹲（单腿负荷更高） | J9: 股四头、臀 | K9: 两种脚位：脚尖朝前 / 脚尖外八；下放至膝约90°，不锁死膝盖 | L9: #C1 4组×10 @180/270/360 lb；脚尖朝前+外八
A10: SQ07 | B10: 腿举等长保持 | C10: SQ | D10: 下肢·蹲（膝主导） | E10: 大 | F10: Leg press isometric hold | G10: 器械 | H10: N | I10: 居家→SQ12 靠墙静蹲（可抱哑铃） | J10: 股四头、臀 | K10: 推起后保持半屈膝静止（1–2分钟） | L10: #10 160 lb 保持1分钟 #37 180 lb 保持2分钟 #69 140 lb 保持1分钟
A11: SQ08 | B11: 腿屈伸 | C11: SQ | D11: 下肢·蹲（膝主导） | E11: 大 | F11: Leg extension | G11: 器械 | H11: N | I11: 居家→SL01 保加利亚分腿蹲 / SQ03 高脚杯深蹲 | J11: 股四头 | K11: 脚尖朝前/外八两种；可做重×5→中×10→轻×15递减 | L11: #10 单腿 20 lb × 12/侧 #22 60 lb × 15 #35 60 lb × 25 #C1 重×5→中×10→轻×15；脚尖朝前+外八
A12: SQ09 | B12: 坐球深蹲 | C12: SQ | D12: 下肢·蹲（膝主导） | E12: 大 | F12: Squat to med ball (box squat) | G12: 药球 | H12: Y | I12: 无药球→蹲坐训练凳 | J12: 股四头、臀 | K12: 药球放身后，蹲至臀部轻触球后快速起立 | L12: #5 18 lb球 × 50（快速）
A13: SQ10 | B13: 徒手深蹲 | C13: SQ | D13: 下肢·蹲（膝主导） | E13: 大 | F13: Air squat | G13: 自重 | H13: Y | J13: 股四头、臀 | K13: 快速节奏，全幅度 | L13: #5 × 25（快速）
A14: SQ11 | B14: 过头沙袋深蹲 | C14: SQ | D14: 下肢·蹲（膝主导） | E14: 大 | F14: Overhead sandbag squat | G14: 沙袋 | H14: Y | I14: 无沙袋→杠铃或单只哑铃过头 | J14: 股四头、肩、核心 | K14: 沙袋举过头锁肘，宽站距深蹲 | L14: #14 × 10
A15: SQ12 | B15: 靠墙静蹲（夹球+举杆） | C15: SQ | D15: 下肢·蹲（膝主导） | E15: 大 | F15: Wall sit with ball squeeze & overhead bar | G15: 药球+短杆 | H15: Y | I15: 无药球→膝间夹瑜伽砖或枕头；举杠铃杆 | J15: 股四头、内收肌、肩 | K15: 背贴墙马步，膝间夹球，双手直臂上举横杆 | L15: #32 膝夹球+直臂举杆
A16: HG01 | B16: 腿弯举（卧/坐） | C16: HG | D16: 下肢·髋铰链（腿后侧/臀） | E16: 大 | F16: Leg curl (lying or seated) | G16: 器械 | H16: N | I16: 居家→TRX 腿弯举（仰卧，脚跟挂悬挂带）/ HG02 罗马尼亚硬拉 | J16: 腘绳肌（腿后筋） | K16: 脚尖朝前/外八；可做重×5→中×10→轻×15递减 | L16: #1 60 lb × 15；第2组做到力竭 #36 65 lb × 20 #C1 重×5→中×10→轻×15；脚尖朝前+外八
A17: HG02 | B17: 罗马尼亚硬拉 | C17: HG | D17: 下肢·髋铰链（腿后侧/臀） | E17: 大 | F17: Romanian deadlift (RDL) | G17: 杠铃 | H17: Y | I17: 杠铃（片≤90 lb + 杆）或双哑铃 | J17: 腘绳肌、臀、竖脊肌 | K17: 微屈膝，臀部后推，挺胸直背，感到腿后侧拉伸后起身 | L17: #38 90 lb × 10
A18: HG03 | B18: 传统硬拉（正反握） | C18: HG | D18: 下肢·髋铰链（腿后侧/臀） | E18: 大 | F18: Conventional deadlift, mixed grip | G18: 杠铃 | H18: Y | I18: 杠铃 | J18: 臀、腘绳肌、背 | K18: 正反握每组交换强弱手；直背，杠铃贴腿 | L18: #76 45 lb × 10，正反握交换
A19: HG04 | B19: 分腿站硬拉 | C19: HG | D19: 下肢·髋铰链（腿后侧/臀） | E19: 大 | F19: Split-stance deadlift | G19: 杠铃/哑铃 | H19: Y | I19: 杠铃或单只哑铃 | J19: 臀、腘绳肌 | K19: 双脚前后分开站立，直背硬拉；正反握 | L19: #34 45 lb 正反握 × 10/侧
A20: HG05 | B20: 壶铃摆荡 | C20: HG | D20: 下肢·髋铰链（腿后侧/臀） | E20: 大 | F20: Kettlebell swing (Russian) | G20: 壶铃 | H20: Y | I20: 无壶铃→单只哑铃竖握摆荡 | J20: 臀、腘绳肌、核心 | K20: 髋部发力把壶铃"甩"到与地面平行，不是用手臂举 | L20: #5 35 lb × 25 #50 35 lb × 15 #65 40 lb #68 30 lb × 20
A21: HG06 | B21: 弹力带臀桥（外展） | C21: HG | D21: 下肢·髋铰链（腿后侧/臀） | E21: 大 | F21: Banded glute bridge with abduction | G21: 弹力带 | H21: Y | I21: 布弹力圈 | J21: 臀中肌、臀大肌 | K21: 弹力带套膝上，仰卧顶髋，膝向外撑，顶点保持3秒 | L21: #32 × 10，顶点3秒
A22: HG07 | B22: 滚轮凳脚跟拖行 | C22: HG | D22: 下肢·髋铰链（腿后侧/臀） | E22: 大 | F22: Rolling-stool hamstring walk | G22: 滚轮凳 | H22: N | I22: 居家→TRX 腿弯举 | J22: 腘绳肌 | K22: 坐在滚轮凳上，用脚跟抓地把身体拉向前 | L22: #15 3趟往返
A23: HG08 | B23: 瑞士球腿弯举 | C23: HG | D23: 下肢·髋铰链（腿后侧/臀） | E23: 大 | F23: Stability-ball hamstring curl | G23: 瑞士球 | H23: N | I23: 无瑞士球→TRX 腿弯举 | J23: 腘绳肌、核心 | K23: 仰卧顶髋，脚跟在球上，屈膝把球拉近再伸直 | L23: #47 × 10
A24: HG09 | B24: 尺蠖爬（腿后侧拉伸） | C24: HG | D24: 下肢·髋铰链（腿后侧/臀） | E24: 大 | F24: Inchworm | G24: 自重 | H24: Y | J24: 腘绳肌、肩、核心 | K24: 直腿弯腰手触地，手向前爬至平板，再走回 | L24: #80 × 10
A25: SL01 | B25: 保加利亚分腿蹲 | C25: SL | D25: 下肢·单腿/侧向 | E25: 大 | F25: Bulgarian split squat | G25: 壶铃/哑铃+凳 | H25: Y | I25: 后脚搭训练凳或 TRX；双手各持哑铃 | J25: 股四头、臀 | K25: 后脚搭凳/悬挂带，前腿下蹲，躯干略前倾 | L25: #22 25 lb × 10/侧
A26: SL02 | B26: 单腿深蹲（抱壶铃） | C26: SL | D26: 下肢·单腿/侧向 | E26: 大 | F26: Single-leg squat to box (goblet) | G26: 壶铃+箱 | H26: Y | I26: 坐训练凳；抱单只哑铃 | J26: 股四头、臀、平衡 | K26: 壶铃抱胸前，单腿坐到箱上再站起 | L26: #38 25 lb × 10/侧
A27: SL03 | B27: 哥萨克深蹲 | C27: SL | D27: 下肢·单腿/侧向 | E27: 大 | F27: Cossack squat | G27: 壶铃 | H27: Y | I27: 单只哑铃 | J27: 内收肌（大腿内侧）、臀 | K27: 宽站距，重心移向一侧深蹲，另一腿伸直脚尖朝上 | L27: #20 45 lb × 10/侧
A28: SL04 | B28: 交叉步（屈膝礼）弓步行进 | C28: SL | D28: 下肢·单腿/侧向 | E28: 大 | F28: Walking curtsy (crossover) lunge | G28: 自重/沙袋/壶铃 | H28: Y | I28: 双手提哑铃 / 杠铃扛肩 | J28: 臀中肌、股四头、内收肌 | K28: 后腿交叉到前腿后方，后膝轻点地；可负重（过头/扛肩/双手提） | L28: #15 沙袋过头，1趟往返 #28 自重，后膝点地+对侧手上举，1趟 #65 40 lb沙袋扛肩，1趟/侧 #68 自重 × 12 #69 双手提25 lb壶铃 × 15
A29: SL05 | B29: 弹力带侧向行走 | C29: SL | D29: 下肢·单腿/侧向 | E29: 大 | F29: Banded lateral walk (monster walk) | G29: 弹力带 | H29: Y | I29: 布弹力圈 | J29: 臀中肌（大腿外侧） | K29: 弹力带套脚踝，半蹲低髋，横向迈步，带子保持张力 | L29: #14 抱沙袋，4步 × 5/侧 #34 黑色弹力带套脚踝，微蹲
A30: SL06 | B30: 壶铃登阶 | C30: SL | D30: 下肢·单腿/侧向 | E30: 大 | F30: Kettlebell step-up | G30: 壶铃+箱 | H30: Y | I30: 踩训练凳（先确认稳固） | J30: 股四头、臀 | K30: 整只脚踩箱，前腿发力上台 | L30: #80 25 lb × 10/侧
A31: SL07 | B31: 壶铃弓步 | C31: SL | D31: 下肢·单腿/侧向 | E31: 大 | F31: Kettlebell lunge | G31: 壶铃 | H31: Y | I31: 双手提哑铃 | J31: 股四头、臀 | K31: 前后脚下蹲至双膝约90° | L31: #49 30 lb × 10/侧
A32: SL08 | B32: 侧弓步推片 | C32: SL | D32: 下肢·单腿/侧向 | E32: 大 | F32: Lateral lunge with plate press-out | G32: 杠铃片 | H32: Y | J32: 内收肌、股四头、肩 | K32: 向侧弓步同时双手把杠铃片向前推出 | L32: #35 35 lb片 × 6/侧
A33: SL09 | B33: 单腿跳箱+落地深蹲 | C33: SL | D33: 下肢·单腿/侧向 | E33: 大 | F33: Single-leg box hop to squat landing | G33: 箱 | H33: N | J33: 股四头、臀、爆发 | K33: 单腿起跳上箱，下箱落地成深蹲 | L33: #56 × 15
A34: SL10 | B34: 低位侧向交叉跳 | C34: SL | D34: 下肢·单腿/侧向 | E34: 大 | F34: Low-stance lateral crossover hop | G34: 自重 | H34: Y | J34: 臀中肌、心肺 | K34: 保持马步低位，左右交叉步跳 | L34: #5 × 12
A35: HPU01 | B35: 坐姿推胸机 | C35: HPU | D35: 上肢·水平推（胸） | E35: 大 | F35: Seated chest press machine | G35: 器械 | H35: N | I35: 居家→HPU04 哑铃卧推 | J35: 胸、前束、三头 | K35: 窄握偏内胸/三头，宽握偏外胸；肩胛后收 | L35: #7 窄握 45 lb × 6 #8 宽握 35 lb × 12；最后一组力竭 #24 45 lb × 10 #51 70 lb × 10 #64 × 15 #C3
A36: HPU02 | B36: 单臂坐姿推胸 | C36: HPU | D36: 上肢·水平推（胸） | E36: 大 | F36: Single-arm chest press | G36: 器械 | H36: N | I36: 居家→单臂哑铃卧推 | J36: 胸、核心抗旋 | K36: 一侧推，躯干不转 | L36: #59 45 lb × 10/侧
A37: HPU03 | B37: 杠铃卧推 | C37: HPU | D37: 上肢·水平推（胸） | E37: 大 | F37: Barbell bench press | G37: 杠铃+卧推凳 | H37: N | I37: 无卧推架，居家不建议杠铃卧推→HPU04 哑铃卧推 | J37: 胸、三头、前束 | K37: 下放至膻中（胸骨中部）轻触，再推起；原记录 35 lb 为每侧加片（总≈115 lb） | L37: #75 每侧35 lb（总≈115 lb）× 10，下放至膻中
A38: HPU04 | B38: 哑铃卧推 | C38: HPU | D38: 上肢·水平推（胸） | E38: 大 | F38: Dumbbell bench press | G38: 哑铃+凳 | H38: Y | J38: 胸、三头 | L38: #35 40 lb × 10
A39: HPU05 | B39: 上斜哑铃卧推 | C39: HPU | D39: 上肢·水平推（胸） | E39: 大 | F39: Incline dumbbell press | G39: 哑铃+可调凳 | H39: Y | J39: 上胸、前束 | K39: 凳子约30° | L39: #18 35 lb × 10
A40: HPU06 | B40: 哑铃/壶铃飞鸟 | C40: HPU | D40: 上肢·水平推（胸） | E40: 大 | F40: Dumbbell flye | G40: 哑铃/壶铃+凳 | H40: Y | I40: 哑铃 | J40: 胸 | K40: 微屈肘，弧线打开再合拢 | L40: #18 20 lb × 15 #32 10 lb壶铃 × 10
...

Sheet 训练组合 Workouts
A1: # | B1: 原始描述（原文） | C1: 原分类 | D1: 新分类 Focus | E1: Focus (EN) | F1: 肌群大小 | G1: 规范描述（中文） | H1: Standardized (English) | I1: 动作ID | J1: 可全部在家 | K1: 待确认
A2: 1 | B2: 2组：15个60lb卧位拉腿后筋，第二组做到极限 | C2: A-1：下肢-腿后筋 | D2: 腿 | E2: Legs | F2: 大 | G2: 【2组】 1. 腿弯举（卧/坐） — 60 lb × 15；第2组做到力竭 | H2: [2 sets] 1. Leg curl (lying or seated) — 60 lb × 15; set 2 to failure | I2: HG01 | J2: N
A3: 2 | B3: 15-12-9-6-3: 单侧70lb杠铃架；卧推杆部队上举；18lb球深蹲抛接；卧跳 | C3: Z-A：综合-下肢-核心力量 | D3: 全身 | E3: Full body | F3: 全身 | G3: 【阶梯 15-12-9-6-3（每轮各动作做对应次数）】 1. 杠铃后蹲 — 每侧70 lb 2. 杠铃站姿推举（军式推举） — 空杆 45 lb 3. 药球墙球 — 18 lb 4. 波比跳 — 自重 | H3: [Ladder 15-12-9-6-3 reps] 1. Barbell back squat — per side 70 lb 2. Barbell overhead / military press — empty bar 45 lb 3. Wall ball — 18 lb 4. Burpee — bodyweight | I3: SQ01, VPU01, PW03, PW01 | J3: N
A4: 3 | B4: 30lb壶铃浅蹲跳上举过头15个；五个全引体向上；260m string pull back; 牵引绳坐位直背上拉10个 | C4: Z-E：综合-上肢-肩背 | D4: 背+肩 | E4: Back + Shoulders | F4: 大+小 | G4: 【1轮循环】 1. 壶铃借力推举 — 30 lb × 15 2. 引体向上 — × 5 3. 划船机 — 260 m 4. 坐姿绳索划船 — × 10 | H4: [1 round (circuit)] 1. Kettlebell push press — 30 lb × 15 2. Pull-up (bodyweight) — × 5 3. Rowing machine (erg) — 260 m 4. Seated cable row — × 10 | I4: VPU04, VPL02, WU02, HPL01 | J4: N
A5: 4 | B5: 26lb壶铃俯卧撑10个；15lb杆仰卧起坐15个；15lb杆子划船10个来回 | C5: Z-F：综合-上肢-后背+腰腹 | D5: 核心 | E5: Core | F5: 小 | G5: 【1轮循环】 1. 握铃俯卧撑 — 26 lb × 10 2. 仰卧起坐（可负重/转体） — 举15 lb杆 × 15 3. 坐姿持杆划桨转体 — 15 lb杆 × 10/侧 | H5: [1 round (circuit)] 1. Push-up on kettlebells / dumbbells — 26 lb × 10 2. Sit-up (weighted / with twist) — holding 15 lb bar overhead × 15 3. Seated bar paddle twist — 15 lb bar × 10 /side | I5: HPU11, CO01, CO16 | J5: Y
A6: 5 | B6: 50个快速深蹲坐18lb球；25个35lb壶铃含胸下摆甩；25个快速深蹲；12个马步交叉步跳 | C6: Z-A：综合-下肢-核心力量 | D6: 腿 | E6: Legs | F6: 大 | G6: 【1轮循环】 1. 坐球深蹲 — 18 lb球 × 50（快速） 2. 壶铃摆荡 — 35 lb × 25 3. 徒手深蹲 — × 25（快速） 4. 低位侧向交叉跳 — × 12 | H6: [1 round (circuit)] 1. Squat to med ball (box squat) — 18 lb ball × 50(fast) 2. Kettlebell swing (Russian) — 35 lb × 25 3. Air squat — × 25(fast) 4. Low-stance lateral crossover hop — × 12 | I6: SQ09, HG05, SQ10, SL10 | J6: Y
A7: 6 | B7: 3组:12开肩全引体向上10个+10个单杠俯卧撑+12收肩全引体向上+10个单杠俯卧撑 | C7: Z-E：综合-上肢-肩背 | D7: 背 | E7: Back | F7: 大 | G7: 【3轮循环】 1. 辅助引体向上（宽/窄握） — 档位12 宽握 × 10 2. 斜杠俯卧撑 — × 10 3. 辅助引体向上（宽/窄握） — 档位12 窄握 × 12 4. 斜杠俯卧撑 — × 10 | H7: [3 rounds (circuit)] 1. Assisted pull-up (wide / close grip) — level 12 wide grip × 10 2. Incline bar push-up — × 10 3. Assisted pull-up (wide / close grip) — level 12 close grip × 12 4. Incline bar push-up — × 10 | I7: VPL01, HPU10 | J7: N
A8: 7 | B8: 4组：45lb窄肩坐推6个； | C8: C: 上肢-胸 | D8: 胸 | E8: Chest | F8: 大 | G8: 【4组】 1. 坐姿推胸机 — 窄握 45 lb × 6 | H8: [4 sets] 1. Seated chest press machine — close grip 45 lb × 6 | I8: HPU01 | J8: N
A9: 8 | B9: 3组: 35lb宽肩坐推12个，最后一组到极限 | C9: C: 上肢-胸 | D9: 胸 | E9: Chest | F9: 大 | G9: 【3组】 1. 坐姿推胸机 — 宽握 35 lb × 12；最后一组力竭 | H9: [3 sets] 1. Seated chest press machine — wide grip 35 lb × 12; last set to failure | I9: HPU01 | J9: N
A10: 9 | B10: 3组: 每侧40lb 杠铃深蹲3秒起立 | C10: Z-A：综合-下肢-核心力量 | D10: 腿 | E10: Legs | F10: 大 | G10: 【3组】 1. 杠铃后蹲 — 每侧40 lb（总≈125 lb），3秒下放 | H10: [3 sets] 1. Barbell back squat — per side 40 lb (total ≈125 lb), 3-s lowering | I10: SQ01 | J10: Y
A11: 10 | B11: 3组:20lb每侧腿单腿折叠12个+ 1min: 双腿折叠坚持160lb | C11: Z-A：综合-下肢-腿-上下 | D11: 腿 | E11: Legs | F11: 大 | G11: 【3组】 1. 腿屈伸 — 单腿 20 lb × 12/侧 2. 腿举等长保持 — 160 lb 保持1分钟 | H11: [3 sets] 1. Leg extension — single-leg 20 lb × 12 /side 2. Leg press isometric hold — 160 lb hold 1 min | I11: SQ08, SQ07 | J11: N
A12: 11 | B12: 3组: 15lb哑铃从垂直位举到与地面平行，打开手肘与地面平行，平行伸直小臂10个 | C12: D: 肩 | D12: 肩 | E12: Shoulders | F12: 小 | G12: 【3组】 1. 哑铃三段肩部组合（古巴推举式） — 15 lb × 10 | H12: [3 sets] 1. Dumbbell Cuban-press complex — 15 lb × 10 | I12: SH02 | J12: Y
A13: 12 | B13: 2组: 15lb哑铃强侧平行地面直举，弱侧交替向前和水平平举各10次，强弱侧交换 | C13: D: 肩 | D13: 肩 | E13: Shoulders | F13: 小 | G13: 【2组】 1. 前/侧平举（对侧静力） — 15 lb × 10/侧 | H13: [2 sets] 1. Front & lateral raise with contralateral iso-hold — 15 lb × 10 /side | I13: SH01 | J13: Y
... A82: 81 | B82: 35磅壶铃深蹲十个，15磅小壶铃蹲起➕直臂10个，吊带斜体牵引10个，脚悬空俯卧撑+高抬臀10个 | C82: Z：综合 | D82: 全身 | E82: Full body | F82: 全身 | G82: 【1轮循环】 1. 高脚杯深蹲 — 35 lb × 10 2. 高脚杯深蹲 — 15 lb + 起身直臂前平举 × 10 3. 悬挂带反向划船 — × 10 4. 悬挂带俯卧撑+收腹/提臀 — 俯卧撑+提臀 × 10 | H82: [1 round (circuit)] 1. Goblet squat (KB/DB) — 35 lb × 10 2. Goblet squat (KB/DB) — 15 lb + straight-arm front raise on the way up × 10 3. Suspension (TRX) inverted row — × 10 4. Suspension push-up + knee tuck / pike — push-up + pike × 10 | I82: SQ03, HPL08, HPU12 | J82: Y
A83: C1 | B83: leg press: 10*4 with 180, 270, and 360lb, both straight toe and toe pointing out leg expansion: toe straight and toe out, heavy weight *5, medium weight *10, light weight* 15 leg curvel: toe straight and toe out, heavy weight *5, medium weight *10, light weight* 15 | C83: 腿 | D83: 腿 | E83: Legs | F83: 大 | G83: 【按动作】 1. 腿举 — 4组×10 @180/270/360 lb；脚尖朝前+外八 2. 腿屈伸 — 重×5→中×10→轻×15；脚尖朝前+外八 3. 腿弯举（卧/坐） — 重×5→中×10→轻×15；脚尖朝前+外八 | H83: [Per exercise] 1. Leg press — 4 sets×10 @180/270/360 lb ; toes forward + toes out 2. Leg extension — heavy×5→medium×10→light×15; toes forward + toes out 3. Leg curl (lying or seated) — heavy×5→medium×10→light×15; toes forward + toes out | I83: SQ06, SQ08, HG01 | J83: N
A84: C2 | B84: high knee walk: shoulder a bar hanging 10lb weight, walk forward and backward 1 leg smarsh 10lb ball:lift the ball above head and smarsh into groud while 1 leg standing yoga block body curve: stand on 2 blocks, leg straight and curve upper body to toe, to expand mussel near butt 1 leg stand on a half soft ball: 20s heavy bar lyfting: 1 leg curve the other straight, lyft the bar from lower body to the top of head towing the rack with weight walk forward and backward | C84: inbalance | D84: 平衡 | E84: Balance | F84: — | G84: 【按动作】 1. 肩扛悬挂负重杆高抬腿走 — 挂10 lb，前进+后退 2. 单腿药球砸地 — 10 lb 3. 站砖体前屈卷背 4. 单腿站BOSU — 20秒 5. 雪橇推/拉 — 负重拖架前进+后退 | H84: [Per exercise] 1. High-knee walk with oscillating bar — 10 lb hanging, forward & backward 2. Single-leg med-ball slam — 10 lb 3. Standing forward fold / Jefferson curl on blocks 4. Single-leg balance on BOSU — 20 s 5. Sled push & drag — weighted drag forward & backward | I84: BL03, BL02, BL04, BL01, PW09 | J84: N
A85: C3 | B85: chest press machine: push up with rubber band, and with weight push with 2 string machine: push upper head, middle of body, and lower boday push ups afterward | C85: chest | D85: 胸 | E85: Chest | F85: 大 | G85: 【按动作】 1. 坐姿推胸机 2. 弹力带/负重俯卧撑 — 弹力带 / 负重 3. 绳索夹胸（高/中/低） — 高/中/低 4. 俯卧撑（标准/宽距/贴地） — 收尾 | H85: [Per exercise] 1. Seated chest press machine 2. Banded or weighted push-up — band / weighted 3. Cable press / fly (high, mid, low) — high/mid/low 4. Push-up (standard / wide / hand-release) — finisher | I85: HPU01, HPU09, HPU07, HPU08 | J85: N
A86: C4 | B86: single string: 1 hand pull with light weight*10, sit and pull with heavy weight *5, sit and pull up and down with light weight *10 2 string machine: 15lb pull upper high, middle and low, 5 times each vertical string: pull down with a bar | C86: back | D86: 背 | E86: Back | F86: 大 | G86: 【按动作】 1. 单臂器械/绳索划船 — 轻 × 10 2. 坐姿绳索划船 — 重 × 5；再高/低位轻 × 10 3. 双绳高/中/低位拉 — 15 lb 高/中/低各 × 5 4. 高位下拉 | H86: [Per exercise] 1. Single-arm machine / cable row — light × 10 2. Seated cable row — heavy × 5; then high/lowlight × 10 3. Cable row – high, mid, low — 15 lb high/mid/loweach × 5 4. Lat pulldown | I86: HPL05, HPL01, HPL09, VPL03 | J86: N
A87: C5 | B87: rubber band press inside and up dumbbell up with locked elbow, and above head standing with string machine: pull up and down | C87: arms and shoulder | D87: 肩+手臂 | E87: Shoulders + Arms | F87: 小 | G87: 【按动作】 1. 弹力带手臂/肩部练习 2. 哑铃弯举（全幅度/锁肘） — 锁肘 3. 坐姿哑铃颈后臂屈伸 — 过头 4. 绳索弯举 — 站姿 5. 绳索下压 — 站姿 | H87: [Per exercise] 1. Band arm & shoulder work 2. Dumbbell curl (full ROM, fixed elbow) — fixed elb ow 3. Seated overhead dumbbell extension — overhead 4. Cable curl — standing 5. Cable triceps pushdown — standing | I87: SH09, BI02, TR04, BI04, TR06 | J87: N
A88: C6 | B88: on the mat: 45 degrees, panjelem, look yr sneakers, russian twist, etc. | C88: core | D88: 核心 | E88: Core | F88: 小 | G88: 【垫上】 1. 45°卷腹 2. 仰卧交替踢腿 3. 抬头看鞋卷腹 4. 俄罗斯转体 | H88: [On the mat] 1. 45° crunch 2. Flutter kick 3. "Look at your sneakers" crunch 4. Russian twist | I88: CO14, CO18, CO17, CO13 | J88: Y

Sheet 周计划 Plan
A1: 健身房 60 分钟结构
A2: 时段 | B2: 内容 | C2: 组×次 | D2: 组间休息 | E2: 说明
A3: 0–8 min | B3: 热身 | C3: — | D3: — | E3: 划船机/跑步机5分钟 + 2个动态激活（如 HPL08、PW06 轻量）
A4: 8–35 min | B4: 大肌群：主项 + 辅项（2–3个动作） | C4: 主项 4×6–8；辅项 3×10–12 | D4: 90–120 s / 60–90 s | E4: 主项用最重的复合动作
A5: 35–50 min | B5: 小肌群：2个动作超级组 | C5: 3×10–15 | D5: 45–60 s | E5: 两个动作交替做，节省时间
A6: 50–57 min | B6: 核心：2个动作 | C6: 2–3组 | D6: 30–45 s | E6: 每次都练
A7: 57–60 min | B7: 拉伸 | C7: — | D7: —
A9: 3周轮转（每周：健身房1次 + 居家1次）
B10: A周：腿 + 肩 | C10: B周：背 + 二头 | D10: C周：胸 + 三头 | E10: 说明
A11: 健身房 大肌群主项 | B11: SQ06 腿举 4×8–10 （家里练不了大重量腿，健身房优先练腿机器） | C11: VPL01 辅助引体 / VPL03 高位下拉 4×8–10 | D11: HPU03 杠铃卧推 4×6–8 （家里没有卧推架） | E11: 健身房练家里做不了的：重腿、器械、绳索
A12: 健身房 大肌群辅项 | B12: SQ08 腿屈伸 3×12 HG01 腿弯举 3×12 | C12: HPL01 坐姿绳索划船 3×10 HPL05 单臂器械划船 3×10/侧 | D12: HPU07 绳索夹胸 高/中/低 3×12 HPU01 推胸机 3×10
A13: 健身房 小肌群超级组 | B13: VPU02 哑铃推举 3×10 + SH01 前/侧平举 3×12 | C13: BI04 绳索弯举 3×12 + BI01 交叉锤式弯举 3×10 | D13: TR06 绳索下压 3×12 + TR01 碎颅者 3×10
A14: 健身房 核心 | B14: CO06 罗马椅举腿 + CO08 平板 | C14: CO03 健腹轮 + CO13 俄罗斯转体 | D14: CO01 负重仰卧起坐 + CO11 BOSU交叉触碰
A15: 居家（40–45分钟） 练另外两个大肌群 | B15: 【背+胸】 VPL02 引体向上 4×力竭（或负离心） HPU04 哑铃卧推 4×10–12（45 lb） HPL04 单臂哑铃划船 3×10/侧 HPU05 上斜哑铃卧推 3×12 HPL08 TRX划船 3×12 CO03 健腹轮 3×10 | C15: 【胸+腿】 HPU04 哑铃卧推 4×10–12 SL01 保加利亚分腿蹲 3×10/侧（双哑铃） HG02 杠铃罗马尼亚硬拉 3×10 HPU06 哑铃飞鸟 3×12 HG06 弹力圈臀桥 2×15 CO04 TRX跪姿展腹 3×10 | D15: 【背+腿】 VPL02 引体向上 4×力竭 HG02 杠铃罗马尼亚硬拉 4×8 SL01 保加利亚分腿蹲 3×10/侧 HPL06 上斜俯卧哑铃划船 3×10 HPL08 TRX划船 3×12 CO07 悬垂举腿 3×10 | E15: 45 lb 哑铃做卧推、划船都够用；腿部单腿动作（分腿蹲）比双腿蹲更能用满家里的重量
A16: 本周练到 | B16: 腿（健身房）+ 背、胸（居家） | C16: 背（健身房）+ 胸、腿（居家） | D16: 胸（健身房）+ 背、腿（居家） | E16: 每周三大肌群都练到；3周内每个大肌群：1次健身房重练 + 2次居家
A18: 进阶规则（双重渐进）：每个动作设次数区间（如 8–10）。所有组都做到上限 → 下次加重 5 lb（下肢可加 10 lb），次数回到下限。
A19: 每做完一轮3周，可把主项换成同类别的其他动作（例如 SQ06 ↔ SQ01 ↔ SQ05），保持新鲜感又不打乱结构。
A20: 若某周只去了健身房、没练居家，下周不补，按顺序继续轮转即可。

Sheet 记录 Log
A1: 日期 Date | B1: 场次 Session | C1: 动作ID | D1: 动作名（自动） | E1: 组号 Set | F1: 重量 lb | G1: 次数 Reps | H1: RPE (1–10) | I1: 备注 | K1: 填写说明：每组一行；只需填 日期/场次/动作ID/重量/次数，动作名会自动带出。
A2: 2026-10-26 | B2: A周-健身房 | C2: SQ06 | D2: =IF(C2="","",IFERROR(INDEX('动作库 Exercises'!$B:$B,MATCH(C2,'动作库 Exercises'!$A:$A,0)),"未找到ID")) -> 腿举 | E2: 1 | F2: 180 | G2: 10 | H2: 7 | I2: 示例行 Example — 可删除
D3: =IF(C3="","",IFERROR(INDEX('动作库 Exercises'!$B:$B,MATCH(C3,'动作库 Exercises'!$A:$A,0)),"未找到ID"))
D4: =IF(C4="","",IFERROR(INDEX('动作库 Exercises'!$B:$B,MATCH(C4,'动作库 Exercises'!$A:$A,0)),"未找到ID"))
D5: =IF(C5="","",IFERROR(INDEX('动作库 Exercises'!$B:$B,MATCH(C5,'动作库 Exercises'!$A:$A,0)),"未找到ID"))
D6: =IF(C6="","",IFERROR(INDEX('动作库 Exercises'!$B:$B,MATCH(C6,'动作库 Exercises'!$A:$A,0)),"未找到ID"))
D7: =IF(C7="","",IFERROR(INDEX('动作库 Exercises'!$B:$B,MATCH(C7,'动作库 Exercises'!$A:$A,0)),"未找到ID"))
D8: =IF(C8="","",IFERROR(INDEX('动作库 Exercises'!$B:$B,MATCH(C8,'动作库 Exercises'!$A:$A,0)),"未找到ID"))
D9: =IF(C9="","",IFERROR(INDEX('动作库 Exercises'!$B:$B,MATCH(C9,'动作库 Exercises'!$A:$A,0)),"未找到ID"))
D10: =IF(C10="","",IFERROR(INDEX('动作库 Exercises'!$B:$B,MATCH(C10,'动作库 Exercises'!$A:$A,0)),"未找到ID"))
D11: =IF(C11="","",IFERROR(INDEX('动作库 Exercises'!$B:$B,MATCH(C11,'动作库 Exercises'!$A:$A,0)),"未找到ID"))
D12: =IF(C12="","",IFERROR(INDEX('动作库 Exercises'!$B:$B,MATCH(C12,'动作库 Exercises'!$A:$A,0)),"未找到ID"))
D13: =IF(C13="","",IFERROR(INDEX('动作库 Exercises'!$B:$B,MATCH(C13,'动作库 Exercises'!$A:$A,0)),"未找到ID"))
D14: =IF(C14="","",IFERROR(INDEX('动作库 Exercises'!$B:$B,MATCH(C14,'动作库 Exercises'!$A:$A,0)),"未找到ID"))
... D501: =IF(C501="","",IFERROR(INDEX('动作库 Exercises'!$B:$B,MATCH(C501,'动作库 Exercises'!$A:$A,0)),"未找到ID"))

Sheet 居家器材 Home gear
A1: 器材 | B1: 规格/上限 | C1: 主要用途
A2: 可调哑铃 ×2 | B2: 每只最高 45 lb | C2: 卧推、划船、推举、弯举、分腿蹲、高脚杯深蹲、摆荡（代替壶铃）
A3: 杠铃杆 + 杠铃片 | B3: 片最多 90 lb（不含杆） | C3: 罗马尼亚硬拉、硬拉、划船、前蹲（无深蹲架，需翻上肩）
A4: 曲杆 EZ bar | B4: — | C4: 碎颅者、仰卧过头臂屈伸、弯举
A5: 可调训练凳 | B5: 无腿屈伸/腿弯举附件 | C5: 卧推、上斜、单臂划船、分腿蹲、凳上臂屈伸
A6: 引体架 | B6: — | C6: 引体向上、悬垂举腿、挂TRX
A7: TRX 悬挂带 | B7: 挂引体架 | C7: 划船、Y/T飞、展腹、俯卧撑收腹、腿弯举
A8: 布弹力圈 ×3 | B8: 三种阻力 | C8: 臀桥外展、侧向行走、热身激活
A9: 健腹轮 | B9: — | C9: 跪姿健腹轮
A10: 瑜伽垫 | B10: — | C10: 核心、拉伸
A12: 缺少（相关动作已标注替代）：壶铃、药球、沙袋、BOSU、瑞士球、跳箱、战绳、深蹲架、卧推架

Sheet 原始记录 Original
A1: Index | B1: Item | C1: Category
A2: 1 | B2: 2组：15个60lb卧位拉腿后筋，第二组做到极限 | C2: A-1：下肢-腿后筋
A3: 2 | B3: 15-12-9-6-3: 单侧70lb杠铃架；卧推杆部队上举；18lb球深蹲抛接；卧跳 | C3: Z-A：综合-下肢-核心力量
A4: 3 | B4: 30lb壶铃浅蹲跳上举过头15个；五个全引体向上；260m string pull back; 牵引绳坐位直背上拉10个 | C4: Z-E：综合-上肢-肩背
A5: 4 | B5: 26lb壶铃俯卧撑10个；15lb杆仰卧起坐15个；15lb杆子划船10个来回 | C5: Z-F：综合-上肢-后背+腰腹
A6: 5 | B6: 50个快速深蹲坐18lb球；25个35lb壶铃含胸下摆甩；25个快速深蹲；12个马步交叉步跳 | C6: Z-A：综合-下肢-核心力量
A7: 6 | B7: 3组:12开肩全引体向上10个+10个单杠俯卧撑+12收肩全引体向上+10个单杠俯卧撑 | C7: Z-E：综合-上肢-肩背
A8: 7 | B8: 4组：45lb窄肩坐推6个； | C8: C: 上肢-胸
A9: 8 | B9: 3组: 35lb宽肩坐推12个，最后一组到极限 | C9: C: 上肢-胸
A10: 9 | B10: 3组: 每侧40lb 杠铃深蹲3秒起立 | C10: Z-A：综合-下肢-核心力量
A11: 10 | B11: 3组:20lb每侧腿单腿折叠12个+ 1min: 双腿折叠坚持160lb | C11: Z-A：综合-下肢-腿-上下
A12: 11 | B12: 3组: 15lb哑铃从垂直位举到与地面平行，打开手肘与地面平行，平行伸直小臂10个 | C12: D: 肩
A13: 12 | B13: 2组: 15lb哑铃强侧平行地面直举，弱侧交替向前和水平平举各10次，强弱侧交换 | C13: D: 肩
... A82: 81 | B82: 35磅壶铃深蹲十个，15磅小壶铃蹲起➕直臂10个，吊带斜体牵引10个，脚悬空俯卧撑+高抬臀10个 | C82: Z：综合
B83: leg press: 10*4 with 180, 270, and 360lb, both straight toe and toe pointing out leg expansion: toe straight and toe out, heavy weight *5, medium weight *10, light weight* 15 leg curvel: toe straight and toe out, heavy weight *5, medium weight *10, light weight* 15 | C83: 腿
B84: high knee walk: shoulder a bar hanging 10lb weight, walk forward and backward 1 leg smarsh 10lb ball:lift the ball above head and smarsh into groud while 1 leg standing yoga block body curve: stand on 2 blocks, leg straight and curve upper body to toe, to expand mussel near butt 1 leg stand on a half soft ball: 20s heavy bar lyfting: 1 leg curve the other straight, lyft the bar from lower body to the top of head towing the rack with weight walk forward and backward | C84: inbalance
B85: chest press machine: push up with rubber band, and with weight push with 2 string machine: push upper head, middle of body, and lower boday push ups afterward | C85: chest
B86: single string: 1 hand pull with light weight*10, sit and pull with heavy weight *5, sit and pull up and down with light weight *10 2 string machine: 15lb pull upper high, middle and low, 5 times each vertical string: pull down with a bar | C86: back
B87: rubber band press inside and up dumbbell up with locked elbow, and above head standing with string machine: pull up and down | C87: arms and shoulder
B88: on the mat: 45 degrees, panjelem, look yr sneakers, russian twist, etc. | C88: core
